[2023-01-07T17:24:39.750+0000] {taskinstance.py:1087} INFO - Dependencies all met for <TaskInstance: process_web_log.scan_for_log manual__2023-01-07T17:24:38.984818+00:00 [queued]>
[2023-01-07T17:24:39.756+0000] {taskinstance.py:1087} INFO - Dependencies all met for <TaskInstance: process_web_log.scan_for_log manual__2023-01-07T17:24:38.984818+00:00 [queued]>
[2023-01-07T17:24:39.757+0000] {taskinstance.py:1283} INFO - 
--------------------------------------------------------------------------------
[2023-01-07T17:24:39.757+0000] {taskinstance.py:1284} INFO - Starting attempt 1 of 1
[2023-01-07T17:24:39.757+0000] {taskinstance.py:1285} INFO - 
--------------------------------------------------------------------------------
[2023-01-07T17:24:39.766+0000] {taskinstance.py:1304} INFO - Executing <Task(PythonOperator): scan_for_log> on 2023-01-07 17:24:38.984818+00:00
[2023-01-07T17:24:39.771+0000] {standard_task_runner.py:55} INFO - Started process 6782 to run task
[2023-01-07T17:24:39.774+0000] {standard_task_runner.py:82} INFO - Running: ['***', 'tasks', 'run', 'process_web_log', 'scan_for_log', 'manual__2023-01-07T17:24:38.984818+00:00', '--job-id', '13', '--raw', '--subdir', 'DAGS_FOLDER/process_web_log.py', '--cfg-path', '/tmp/tmpwvhu6nku']
[2023-01-07T17:24:39.775+0000] {standard_task_runner.py:83} INFO - Job 13: Subtask scan_for_log
[2023-01-07T17:24:39.822+0000] {task_command.py:389} INFO - Running <TaskInstance: process_web_log.scan_for_log manual__2023-01-07T17:24:38.984818+00:00 [running]> on host 2b5d58090cce
[2023-01-07T17:24:39.867+0000] {taskinstance.py:1513} INFO - Exporting the following env vars:
AIRFLOW_CTX_DAG_OWNER=***
AIRFLOW_CTX_DAG_ID=process_web_log
AIRFLOW_CTX_TASK_ID=scan_for_log
AIRFLOW_CTX_EXECUTION_DATE=2023-01-07T17:24:38.984818+00:00
AIRFLOW_CTX_TRY_NUMBER=1
AIRFLOW_CTX_DAG_RUN_ID=manual__2023-01-07T17:24:38.984818+00:00
[2023-01-07T17:24:39.871+0000] {taskinstance.py:1772} ERROR - Task failed with exception
Traceback (most recent call last):
  File "/home/airflow/.local/lib/python3.7/site-packages/airflow/operators/python.py", line 175, in execute
    return_value = self.execute_callable()
  File "/home/airflow/.local/lib/python3.7/site-packages/airflow/operators/python.py", line 192, in execute_callable
    return self.python_callable(*self.op_args, **self.op_kwargs)
  File "/opt/airflow/dags/process_web_log.py", line 8, in log_exists
    if 'log.txt' in os.listdir('/airflow-docker/the_logs'):
FileNotFoundError: [Errno 2] No such file or directory: '/airflow-docker/the_logs'
[2023-01-07T17:24:39.877+0000] {taskinstance.py:1327} INFO - Marking task as FAILED. dag_id=process_web_log, task_id=scan_for_log, execution_date=20230107T172438, start_date=20230107T172439, end_date=20230107T172439
[2023-01-07T17:24:39.884+0000] {standard_task_runner.py:105} ERROR - Failed to execute job 13 for task scan_for_log ([Errno 2] No such file or directory: '/airflow-docker/the_logs'; 6782)
[2023-01-07T17:24:39.906+0000] {local_task_job.py:159} INFO - Task exited with return code 1
[2023-01-07T17:24:39.920+0000] {taskinstance.py:2582} INFO - 0 downstream tasks scheduled from follow-on schedule check
