[2023-01-07T17:09:15.866+0000] {taskinstance.py:1087} INFO - Dependencies all met for <TaskInstance: process_web_log.scan_for_log manual__2023-01-07T17:09:15.087428+00:00 [queued]>
[2023-01-07T17:09:15.872+0000] {taskinstance.py:1087} INFO - Dependencies all met for <TaskInstance: process_web_log.scan_for_log manual__2023-01-07T17:09:15.087428+00:00 [queued]>
[2023-01-07T17:09:15.873+0000] {taskinstance.py:1283} INFO - 
--------------------------------------------------------------------------------
[2023-01-07T17:09:15.873+0000] {taskinstance.py:1284} INFO - Starting attempt 1 of 1
[2023-01-07T17:09:15.873+0000] {taskinstance.py:1285} INFO - 
--------------------------------------------------------------------------------
[2023-01-07T17:09:15.884+0000] {taskinstance.py:1304} INFO - Executing <Task(PythonOperator): scan_for_log> on 2023-01-07 17:09:15.087428+00:00
[2023-01-07T17:09:15.889+0000] {standard_task_runner.py:55} INFO - Started process 5455 to run task
[2023-01-07T17:09:15.893+0000] {standard_task_runner.py:82} INFO - Running: ['***', 'tasks', 'run', 'process_web_log', 'scan_for_log', 'manual__2023-01-07T17:09:15.087428+00:00', '--job-id', '6', '--raw', '--subdir', 'DAGS_FOLDER/process_web_log.py', '--cfg-path', '/tmp/tmp5fn5336u']
[2023-01-07T17:09:15.893+0000] {standard_task_runner.py:83} INFO - Job 6: Subtask scan_for_log
[2023-01-07T17:09:15.941+0000] {task_command.py:389} INFO - Running <TaskInstance: process_web_log.scan_for_log manual__2023-01-07T17:09:15.087428+00:00 [running]> on host 2b5d58090cce
[2023-01-07T17:09:15.987+0000] {taskinstance.py:1513} INFO - Exporting the following env vars:
AIRFLOW_CTX_DAG_OWNER=***
AIRFLOW_CTX_DAG_ID=process_web_log
AIRFLOW_CTX_TASK_ID=scan_for_log
AIRFLOW_CTX_EXECUTION_DATE=2023-01-07T17:09:15.087428+00:00
AIRFLOW_CTX_TRY_NUMBER=1
AIRFLOW_CTX_DAG_RUN_ID=manual__2023-01-07T17:09:15.087428+00:00
[2023-01-07T17:09:15.988+0000] {taskinstance.py:1772} ERROR - Task failed with exception
Traceback (most recent call last):
  File "/home/airflow/.local/lib/python3.7/site-packages/airflow/operators/python.py", line 175, in execute
    return_value = self.execute_callable()
  File "/home/airflow/.local/lib/python3.7/site-packages/airflow/operators/python.py", line 192, in execute_callable
    return self.python_callable(*self.op_args, **self.op_kwargs)
  File "/opt/airflow/dags/process_web_log.py", line 8, in log_exists
    if "log.txt" in os.listdir('/the_logs'):
FileNotFoundError: [Errno 2] No such file or directory: '/the_logs'
[2023-01-07T17:09:15.995+0000] {taskinstance.py:1327} INFO - Marking task as FAILED. dag_id=process_web_log, task_id=scan_for_log, execution_date=20230107T170915, start_date=20230107T170915, end_date=20230107T170915
[2023-01-07T17:09:16.003+0000] {standard_task_runner.py:105} ERROR - Failed to execute job 6 for task scan_for_log ([Errno 2] No such file or directory: '/the_logs'; 5455)
[2023-01-07T17:09:16.024+0000] {local_task_job.py:159} INFO - Task exited with return code 1
[2023-01-07T17:09:16.043+0000] {taskinstance.py:2582} INFO - 0 downstream tasks scheduled from follow-on schedule check
