[2023-01-07T19:57:38.988+0000] {taskinstance.py:1087} INFO - Dependencies all met for <TaskInstance: process_web_log.load_data manual__2023-01-07T19:57:35.458312+00:00 [queued]>
[2023-01-07T19:57:38.995+0000] {taskinstance.py:1087} INFO - Dependencies all met for <TaskInstance: process_web_log.load_data manual__2023-01-07T19:57:35.458312+00:00 [queued]>
[2023-01-07T19:57:38.995+0000] {taskinstance.py:1283} INFO - 
--------------------------------------------------------------------------------
[2023-01-07T19:57:38.996+0000] {taskinstance.py:1284} INFO - Starting attempt 1 of 1
[2023-01-07T19:57:38.996+0000] {taskinstance.py:1285} INFO - 
--------------------------------------------------------------------------------
[2023-01-07T19:57:39.005+0000] {taskinstance.py:1304} INFO - Executing <Task(PythonOperator): load_data> on 2023-01-07 19:57:35.458312+00:00
[2023-01-07T19:57:39.010+0000] {standard_task_runner.py:55} INFO - Started process 12112 to run task
[2023-01-07T19:57:39.013+0000] {standard_task_runner.py:82} INFO - Running: ['***', 'tasks', 'run', 'process_web_log', 'load_data', 'manual__2023-01-07T19:57:35.458312+00:00', '--job-id', '52', '--raw', '--subdir', 'DAGS_FOLDER/process_web_log.py', '--cfg-path', '/tmp/tmp5fz9zups']
[2023-01-07T19:57:39.014+0000] {standard_task_runner.py:83} INFO - Job 52: Subtask load_data
[2023-01-07T19:57:39.065+0000] {task_command.py:389} INFO - Running <TaskInstance: process_web_log.load_data manual__2023-01-07T19:57:35.458312+00:00 [running]> on host b2d09a0fd3c2
[2023-01-07T19:57:39.128+0000] {taskinstance.py:1513} INFO - Exporting the following env vars:
AIRFLOW_CTX_DAG_OWNER=***
AIRFLOW_CTX_DAG_ID=process_web_log
AIRFLOW_CTX_TASK_ID=load_data
AIRFLOW_CTX_EXECUTION_DATE=2023-01-07T19:57:35.458312+00:00
AIRFLOW_CTX_TRY_NUMBER=1
AIRFLOW_CTX_DAG_RUN_ID=manual__2023-01-07T19:57:35.458312+00:00
[2023-01-07T19:57:39.129+0000] {taskinstance.py:1772} ERROR - Task failed with exception
Traceback (most recent call last):
  File "/home/airflow/.local/lib/python3.7/site-packages/airflow/operators/python.py", line 175, in execute
    return_value = self.execute_callable()
  File "/home/airflow/.local/lib/python3.7/site-packages/airflow/operators/python.py", line 192, in execute_callable
    return self.python_callable(*self.op_args, **self.op_kwargs)
  File "/opt/airflow/dags/process_web_log.py", line 37, in export_tar
    file = tarfile.open('/the_logs/weblog.tar', 'w+')
  File "/usr/local/lib/python3.7/tarfile.py", line 1615, in open
    raise ValueError("undiscernible mode")
ValueError: undiscernible mode
[2023-01-07T19:57:39.136+0000] {taskinstance.py:1327} INFO - Marking task as FAILED. dag_id=process_web_log, task_id=load_data, execution_date=20230107T195735, start_date=20230107T195738, end_date=20230107T195739
[2023-01-07T19:57:39.145+0000] {standard_task_runner.py:105} ERROR - Failed to execute job 52 for task load_data (undiscernible mode; 12112)
[2023-01-07T19:57:39.185+0000] {local_task_job.py:159} INFO - Task exited with return code 1
[2023-01-07T19:57:39.199+0000] {taskinstance.py:2582} INFO - 0 downstream tasks scheduled from follow-on schedule check
