[2023-01-07T17:44:17.658+0000] {taskinstance.py:1087} INFO - Dependencies all met for <TaskInstance: process_web_log.extract_data manual__2023-01-07T17:44:15.898643+00:00 [queued]>
[2023-01-07T17:44:17.667+0000] {taskinstance.py:1087} INFO - Dependencies all met for <TaskInstance: process_web_log.extract_data manual__2023-01-07T17:44:15.898643+00:00 [queued]>
[2023-01-07T17:44:17.667+0000] {taskinstance.py:1283} INFO - 
--------------------------------------------------------------------------------
[2023-01-07T17:44:17.668+0000] {taskinstance.py:1284} INFO - Starting attempt 1 of 1
[2023-01-07T17:44:17.668+0000] {taskinstance.py:1285} INFO - 
--------------------------------------------------------------------------------
[2023-01-07T17:44:17.683+0000] {taskinstance.py:1304} INFO - Executing <Task(PythonOperator): extract_data> on 2023-01-07 17:44:15.898643+00:00
[2023-01-07T17:44:17.689+0000] {standard_task_runner.py:55} INFO - Started process 729 to run task
[2023-01-07T17:44:17.693+0000] {standard_task_runner.py:82} INFO - Running: ['***', 'tasks', 'run', 'process_web_log', 'extract_data', 'manual__2023-01-07T17:44:15.898643+00:00', '--job-id', '29', '--raw', '--subdir', 'DAGS_FOLDER/process_web_log.py', '--cfg-path', '/tmp/tmpztnp20yn']
[2023-01-07T17:44:17.694+0000] {standard_task_runner.py:83} INFO - Job 29: Subtask extract_data
[2023-01-07T17:44:17.744+0000] {task_command.py:389} INFO - Running <TaskInstance: process_web_log.extract_data manual__2023-01-07T17:44:15.898643+00:00 [running]> on host b2d09a0fd3c2
[2023-01-07T17:44:17.792+0000] {taskinstance.py:1513} INFO - Exporting the following env vars:
AIRFLOW_CTX_DAG_OWNER=***
AIRFLOW_CTX_DAG_ID=process_web_log
AIRFLOW_CTX_TASK_ID=extract_data
AIRFLOW_CTX_EXECUTION_DATE=2023-01-07T17:44:15.898643+00:00
AIRFLOW_CTX_TRY_NUMBER=1
AIRFLOW_CTX_DAG_RUN_ID=manual__2023-01-07T17:44:15.898643+00:00
[2023-01-07T17:44:17.793+0000] {taskinstance.py:1772} ERROR - Task failed with exception
Traceback (most recent call last):
  File "/home/airflow/.local/lib/python3.7/site-packages/airflow/operators/python.py", line 175, in execute
    return_value = self.execute_callable()
  File "/home/airflow/.local/lib/python3.7/site-packages/airflow/operators/python.py", line 192, in execute_callable
    return self.python_callable(*self.op_args, **self.op_kwargs)
  File "/opt/airflow/dags/process_web_log.py", line 15, in extract_ip_address
    with open('/the_logs/log.txt', 'r') as log:
FileNotFoundError: [Errno 2] No such file or directory: '/the_logs/log.txt'
[2023-01-07T17:44:17.800+0000] {taskinstance.py:1327} INFO - Marking task as FAILED. dag_id=process_web_log, task_id=extract_data, execution_date=20230107T174415, start_date=20230107T174417, end_date=20230107T174417
[2023-01-07T17:44:17.808+0000] {standard_task_runner.py:105} ERROR - Failed to execute job 29 for task extract_data ([Errno 2] No such file or directory: '/the_logs/log.txt'; 729)
[2023-01-07T17:44:17.824+0000] {local_task_job.py:159} INFO - Task exited with return code 1
[2023-01-07T17:44:17.837+0000] {taskinstance.py:2582} INFO - 0 downstream tasks scheduled from follow-on schedule check
